#VRML_SIM R2022b utf8

EXTERNPROTO "https://raw.githubusercontent.com/cyberbotics/webots/R2022b/projects/objects/backgrounds/protos/TexturedBackground.proto"
EXTERNPROTO "https://raw.githubusercontent.com/cyberbotics/webots/R2022b/projects/objects/backgrounds/protos/TexturedBackgroundLight.proto"
EXTERNPROTO "https://raw.githubusercontent.com/cyberbotics/webots/R2022b/projects/objects/floors/protos/RectangleArena.proto"

WorldInfo {
}
Viewpoint {
  orientation -0.3485737274310214 0.46778375648084897 0.8122036159224544 1.484758660148662
  position -0.3821577044032821 -1.4124676217874044 1.5646136098165886
}
TexturedBackground {
}
TexturedBackgroundLight {
}
RectangleArena {
}
Robot {
  children [
    Solid {
      children [
        HingeJoint {
          jointParameters HingeJointParameters {
          }
          endPoint Solid {
            children [
              DEF wheel Shape {
                geometry Cylinder {
                  height 0.1
                  radius 0.05
                }
              }
            ]
          }
        }
        Shape {
          geometry Cylinder {
            height 0.1
            radius 0.05
          }
        }
      ]
    }
  ]
}
